ERROR:root:


02/28/2023, 00:13:33
['  File "exception_logger.py", line 20, in <module>\n    log_exceptions(str(traceback.format_stack()))\n']
Traceback (most recent call last):
  File "exception_logger.py", line 18, in <module>
    x = 5 / 0
ZeroDivisionError: division by zero
